Workbook

Sheet ปรับแผนงบลงทุน
A1: ฟอร์มปรับแผนบลงทุนครุภัณฑ์ ประจำปีงบประมาณ 2568
A2: กลุ่มงาน............................................................หน่วยงาน โรงพยาบาลอุตรดิตถ์
A3: ลำดับที่ | B3: ชื่อรายการครุภัณฑ์ที่มิใช่ทางการแพทย์ | C3: รหัสครุภัณฑ์ กบรส | D3: รหัสครุภัณฑ์ | E3: หน่วยนับ | F3: จำนวนที่ขอซื้อ | H3: ราคาต่อหน่วย (บาท) | I3: รวมเงิน (บาท) | J3: ราคากลาง ( กบรส ) | K3: เหตุผลความจำเป็นในการจัดหา (ไม่เกิน 5 บรรทัด) | L3: หน่วยงาน | M3: เลขครุภัณฑ์เดิม | N3: รหัสแหล่งเงิน | O3: รหัสหน่วยงาน
F4: ใหม่ | G4: ทดแทน
B19: รวมทั้งสิ้น | I19: =SUM(I5:I18) -> 0

Sheet วัสดุทั่วไป
B1: ปรับแผนปฏิบัติการจัดซื้อจัดจ้าง ประเภท วัสดุทั่วไป / จ้างเหมาทั่วไป
B2: หน่วยงาน.......................................โรงพยาบาลอุตรดิตถ์ จังหวัด อุตรดิตถ์ รหัสหน่วยงาน 5 หลัก 10673
B3: ประจำปีงบประมาณ พ.ศ. 2569
A5: ลำดับที่ | B5: ลำดับแผน | C5: รายการ | D5: รหัส | E5: ขนาดบรรจุ | F5: ซื้อแล้ว | G5: อัตราการ | H5: คงคลัง | I5: แผนอนุมัติ | J5: แผนจัดซื้อเดิม | M5: แผนจัดซื้อใหม่ | P5: มูลค่าปรับแผน | Q5: มูลค่าปรับแผน | R5: มูลค่าปรับแผน | S5: มูลปรับแผน | T5: เหตุผลการปรับแผน | U5: หน่วยงาน | V5: หมายเหตุ
B6: เดิม | E6: (หน่วยนับ) | F6: เท่าไหร่ | G6: ใช้/ปี | J6: จำนวน (หน่วยนับ) | K6: ราคาต่อหน่วย (บาท) | L6: มูลค่า (บาท) | M6: จำนวน (หน่วยนับ) | N6: ราคาต่อหน่วย (บาท) | O6: มูลค่า (บาท) | P6: บาท | Q6: ครั้งที่2 | R6: ครั้งที่ 1 | S6: สะสม
V7: =VLOOKUP(C7,Sheet3!$1:$1048576,2,) -> #N/A
V8: =VLOOKUP(C8,Sheet3!$1:$1048576,2,) -> #N/A
V9: =VLOOKUP(C9,Sheet3!$1:$1048576,2,) -> #N/A
V10: =VLOOKUP(C10,Sheet3!$1:$1048576,2,) -> #N/A
V11: =VLOOKUP(C11,Sheet3!$1:$1048576,2,) -> #N/A
V12: =VLOOKUP(C12,Sheet3!$1:$1048576,2,) -> #N/A
V13: =VLOOKUP(C13,Sheet3!$1:$1048576,2,) -> #N/A
V14: =VLOOKUP(C14,Sheet3!$1:$1048576,2,) -> #N/A
V15: =VLOOKUP(C15,Sheet3!$1:$1048576,2,) -> #N/A
V16: =VLOOKUP(C16,Sheet3!$1:$1048576,2,) -> #N/A
V17: =VLOOKUP(C17,Sheet3!$1:$1048576,2,) -> #N/A
V18: =VLOOKUP(C18,Sheet3!$1:$1048576,2,) -> #N/A
... V35: =VLOOKUP(C35,Sheet3!$1:$1048576,2,) -> #N/A
C37: รวมทั้งสิ้น | I37: =SUM(I7:I36) -> 0 | L37: =SUM(L7:L36) -> 0 | O37: =SUM(O7:O36) -> 0 | P37: =SUM(P7:P36) -> 0 | Q37: =SUM(Q7:Q36) -> 0 | R37: =SUM(R7:R36) -> 0 | S37: =SUM(S7:S36) -> 0

Sheet Sheet3
A1: item_name | B1: item_id | C1: item_unit | D1: item_type | E1: item_use_status | F1: item_standard_price | G1: item_unit_qty | H1: item_package_name | I1: icode | J1: reorder_level | K1: reorder_qty | L1: standard_code | M1: dummy_left_qty | N1: dummy_left_price | O1: unit_cost | P1: item_sub_unit_qty | Q1: old_unit_cost | R1: oldcode | S1: newcode | T1: default_department_id | U1: fix_department | V1: stock_item_cost_type_id | W1: stock_class_id | X1: barcode_number | Y1: unit_price | Z1: item_code | AA1: hos_guid | AB1: gpo_code | AC1: didstd_code | AD1: avg_month_use_qty | AE1: item_regno | AF1: bdg_nextyear_percent | AG1: stock_item_regdate | AH1: item_note | AI1: safety_stock | AJ1: onhand_qty | AK1: avg_lead_day | AL1: last_active_date | AM1: gpo_vmi | AN1: balance_qty | AO1: item_eng | AP1: item_trand | AQ1: item_type_group | AR1: item_status_control | AS1: item_van_type | AT1: search_keyword | AU1: abc | AV1: ved_code | AW1: pharmacology_group1 | AX1: pharmacology_group2 | AY1: pharmacology_group3 | AZ1: last_po_date | BA1: item_common_name | BB1: stock_item_mtr_id | BC1: stock_item_acct_id | BD1: stock_sub_class_id | BE1: item_trade_name | BF1: stock_item_note | BG1: last_po_price | BH1: stock_item_std_price | BI1: stock_item_ref_price | BJ1: vat_percent | BK1: expire_qty | BL1: supplier_list_text | BM1: vendor_list_text | BN1: po_wait_qty | BO1: last_deliver_date | BP1: item_min_qty | BQ1: item_max_qty | BR1: last_po_price_1 | BS1: sap_unit_name | BT1: sap_item_name | BU1: sap_unit_cost | BV1: sap_active | BW1: manufacturer_list_text | BX1: use_fixed_avg_cost | BY1: fixed_avg_cost | BZ1: stock_mrp_order_type_id | CA1: stock_mrp_lot_size | CB1: last_stock_vendor_id | CC1: stock_item_ed_type_id | CD1: last_calc_si_map | CE1: apply_vat | CF1: update_datetime | CG1: drugitems_no_substock | CH1: gpsc_code | CI1: item_color | CJ1: ttmt_code
A2: T locking plate | B2: 11590 | C2: ชิ้น | D2: 26 | E2: Y | O2: 0 | V2: 1 | W2: 13 | Z2: 004-02-160-018 | AG2: 45865 | BA2: T locking plate | BC2: 6 | BE2: T locking plate | CG2: Y
A3: [ปิดใช้งาน]กระดาษ A4 ขนาด 80 แกรม | B3: 3153 | C3: รีม | D3: 11 | E3: N | O3: 120 | V3: 1 | Y3: 149 | Z3: PI-0010350415 | AG3: 45865 | AJ3: 0 | BA3: กระดาษ A4 ขนาด 80 แกรม | BB3: 1 | BC3: 12 | BE3: กระดาษ A4 ขนาด 80 แกรม | BK3: 0 | BL3: บริษัท ศรีพงษ์กรุ๊ป มาร์เก็ตติ้ง จำกัด | BM3: บริษัท ศรีพงษ์กรุ๊ป มาร์เก็ตติ้ง จำกัด | BN3: 0 | CD3: 2025-08-13 08:48:10.980075 | CF3: 45882.702 | CG3: Y
A4: Hepatitis B immunoglobulin-180 iu/ml-1ml (HBIG)=IMMUNO HBS | B4: 8529 | C4: ขวด | D4: 1 | E4: Y | J4: 9 | K4: 20 | O4: 2457.3034 | R4: 1001368 | V4: 1 | W4: 52 | Y4: 2764 | Z4: B150100-020 | AG4: 45865 | AJ4: 0 | AL4: 45901 | AU4: C | AZ4: 45840 | BA4: Hepatitis B immunoglobulin-180 iu/ml-1ml | BB4: 1 | BC4: 4 | BD4: 6 | BE4: HBIG 180 U/ml-1ml#inj | BF4: เมื่อยาหมดแล้ว เปลี่ยนไปซื้อ 200 IU/ml ศูนย์บริการโลหิตแห่งชาติ สภากาชาดไทย รหัส B150100-002 ราคา 1500/ขวด (ยกเว้นภาษีมูลค่าเพิ่ม) | BG4: 2700 | BK4: 0 | BL4: บริษัท ไบโอจีนีเทค จำกัด | BM4: บริษัท ไบโอจีนีเทค จำกัด | BN4: 0 | BO4: 45901 | BP4: 6 | BQ4: 29 | BR4: 2700 | CB4: 589 | CC4: 1 | CD4: 2025-12-26 13:56:56.749386 | CF4: 45952.667 | CG4: N | CH4: 99000051201600
A5: Mixter clamps 28 cms. | B5: 13094 | C5: ชิ้น | D5: 26 | E5: Y | V5: 1 | W5: 17 | Z5: OR04-05-001-004 | AG5: 45865 | BA5: Mixter clamps 28 cms. | BB5: 1 | BC5: 6 | BE5: Mixter clamps 28 cms. | CF5: 45999.648 | CG5: Y
A6: จ้างเหมาทำป้ายพร้อมขาตั้ง | B6: 14111 | C6: ชุด | D6: 57 | E6: Y | AG6: 45972 | BA6: จ้างเหมาทำป้ายพร้อมขาตั้ง | BB6: 1 | BC6: 57 | BE6: จ้างเหมาทำป้ายพร้อมขาตั้ง | CF6: 45972.362 | CG6: Y
A7: Tap 0.4-4.0 mm cancelous (thread) | B7: 11593 | C7: ชิ้น | D7: 26 | E7: Y | O7: 2450 | V7: 1 | W7: 13 | Z7: 004-02-179-003 | AG7: 45865 | BA7: Tap 0.4-4.0 mm cancelous (thread) | BC7: 6 | BE7: Tap 0.4-4.0 mm cancelous (thread) | CG7: Y
A8: Tapered 1.5x11.1 mm for midas Rex | B8: 11596 | C8: ชิ้น | D8: 26 | E8: Y | O8: 4500 | V8: 1 | W8: 11 | Z8: 004-06-166-009 | AG8: 45865 | BA8: Tapered 1.5x11.1 mm for midas Rex | BC8: 6 | BE8: Tapered 1.5x11.1 mm for midas Rex | CG8: Y
A9: Tapered 2.3x16.4 mm for midas Rex | B9: 11597 | C9: ชิ้น | D9: 26 | E9: Y | O9: 4500 | V9: 1 | W9: 11 | Z9: 004-06-166-008 | AG9: 45865 | BA9: Tapered 2.3x16.4 mm for midas Rex | BC9: 6 | BE9: Tapered 2.3x16.4 mm for midas Rex | CG9: Y
A10: Taylor spinal retractor | B10: 11599 | C10: ชิ้น | D10: 26 | E10: Y | O10: 4500 | V10: 1 | W10: 13 | Z10: OR02-10-001-001 | AG10: 45865 | BA10: Taylor spinal retractor | BC10: 6 | BE10: Taylor spinal retractor | CG10: Y
A11: Pear shape diamond 808/014 | B11: 463 | C11: ตัว | D11: 14 | E11: Y | O11: 85 | V11: 1 | Y11: 103 | Z11: DM-01-E1-0020 | AG11: 45865 | AJ11: 0 | BA11: Pear shape diamond 808/014 | BC11: 9 | BE11: Pear shape diamond 808/014 | BK11: 0 | BN11: 0 | CD11: 2025-12-22 18:16:40.058241 | CG11: Y
A12: Surgical needle cutting edge 3/8 curve 32 mm. | B12: 11557 | C12: ชิ้น | D12: 26 | E12: Y | O12: 16.66667 | V12: 1 | W12: 9 | Z12: 004-14-002-003 | AG12: 45865 | BA12: Surgical needle cutting edge 3/8 curve 32 mm. | BC12: 6 | BE12: Surgical needle cutting edge 3/8 curve 32 mm. | CG12: Y
A13: Pear shape diamond 808/012 | B13: 462 | C13: ตัว | D13: 14 | E13: Y | O13: 85 | V13: 1 | Y13: 103 | Z13: DM-01-E1-0019 | AG13: 45865 | AJ13: 0 | BA13: Pear shape diamond 808/012 | BC13: 9 | BE13: Pear shape diamond 808/012 | BK13: 0 | BN13: 0 | CD13: 2025-12-22 18:16:39.978186 | CG13: Y
A14: Tibia proximal medial locking5.0 Rt. 9h. | B14: 11625 | C14: ชิ้น | D14: 26 | E14: Y | O14: 11500 | V14: 1 | W14: 13 | Z14: 004-02-171-006 | AG14: 45865 | BA14: Tibia proximal medial locking5.0 Rt. 9h. | BC14: 6 | BE14: Tibia proximal medial locking5.0 Rt. 9h. | CG14: Y
A15: Paperpoint No.SS | B15: 455 | C15: กล่อง | D15: 14 | E15: Y | O15: 60 | V15: 1 | Y15: 73 | Z15: DM-01-C2-0001 | AG15: 45865 | AJ15: 5 | BA15: Paperpoint No.SS | BC15: 9 | BE15: Paperpoint No.SS | BK15: 0 | BN15: 0 | CD15: 2025-12-22 18:16:39.33668 | CG15: Y
A16: Fuji IX capsule | B16: 230 | C16: กล่อง | D16: 14 | E16: Y | O16: 2000 | V16: 1 | Y16: 2261 | Z16: DM-01-B1-0020 | AG16: 45865 | AJ16: 1 | BA16: Fuji IX capsule | BC16: 9 | BE16: Fuji IX capsule | BK16: 0 | BN16: 0 | CD16: 2025-12-22 18:16:39.207209 | CG16: Y
A17: Tubbing occlusion clamps 20 cms. | B17: 13092 | C17: ชิ้น | D17: 26 | E17: Y | V17: 1 | Z17: OR12-07-001-002 | AG17: 45865 | BA17: Tubbing occlusion clamps 20 cms. | BC17: 6 | BE17: Tubbing occlusion clamps 20 cms. | CG17: Y
A18: Round diamond 801/023 | B18: 522 | C18: ตัว | D18: 14 | E18: Y | O18: 95 | V18: 1 | Y18: 115 | Z18: DM-01-E1-0009 | AG18: 45865 | AJ18: 0 | BA18: Round diamond 801/023 | BC18: 9 | BE18: Round diamond 801/023 | BK18: 0 | BN18: 0 | CD18: 2025-12-22 18:16:40.000186 | CG18: Y
A19: Microbrush | B19: 397 | C19: กล่อง | D19: 14 | E19: Y | O19: 120 | V19: 1 | Y19: 149 | Z19: DM-01-C1-0126 | AG19: 45865 | AJ19: 0 | BA19: Microbrush | BC19: 9 | BE19: Microbrush | BK19: 0 | BN19: 0 | CD19: 2025-12-22 18:16:39.808222 | CG19: Y
A20: Self etching bonding | B20: 549 | C20: ชุด | D20: 14 | E20: Y | O20: 3317 | V20: 1 | Y20: 3710 | Z20: DM-01-C1-0026 | AG20: 45865 | AJ20: 0 | BA20: Self etching bonding | BC20: 9 | BE20: Self etching bonding | BK20: 0 | BN20: 0 | CD20: 46013.762 | CG20: Y
A21: 661 HP ขาว | B21: 2 | C21: ตัว | D21: 14 | E21: Y | O21: 95 | V21: 1 | Y21: 115 | Z21: DM-01-E4-0009 | AG21: 45865 | AJ21: 0 | AL21: 45875 | AZ21: 45846 | BA21: 661 HP ขาว | BC21: 9 | BE21: 661 HP ขาว | BG21: 95 | BK21: 0 | BN21: 0 | BO21: 45875 | BR21: 95 | CB21: 422 | CD21: 2025-12-22 18:15:38.252226 | CG21: Y
A22: เมนเบรคเกอร์ 50A | B22: 5681 | C22: ตัว | D22: 10 | E22: Y | O22: 880 | V22: 1 | Y22: 1023 | Z22: PI-0030220004 | AG22: 45865 | AJ22: 0 | AL22: 45918 | AZ22: 45887 | BA22: เมนเบรคเกอร์ 50A | BC22: 15 | BE22: เมนเบรคเกอร์ 50A | BG22: 880 | BK22: 0 | BN22: 0 | BO22: 45918 | BR22: 880 | CB22: 1755 | CD22: 2025-12-22 18:17:27.57572 | CG22: Y
A23: Round diamond 801/014 | B23: 518 | C23: ตัว | D23: 14 | E23: Y | O23: 95 | V23: 1 | Y23: 115 | Z23: DM-01-E1-0005 | AG23: 45865 | AJ23: 40 | AL23: 45875 | AZ23: 45846 | BA23: Round diamond 801/014 | BC23: 9 | BE23: Round diamond 801/014 | BG23: 95 | BK23: 0 | BN23: 0 | BO23: 45875 | BR23: 95 | CB23: 422 | CD23: 2025-12-22 18:15:38.425738 | CG23: Y
A24: Hemoclip large(สีส้ม) | B24: 10717 | C24: ตัว | D24: 26 | E24: Y | O24: 47.33307 | V24: 1 | W24: 6 | Y24: 58 | Z24: 004-06-035-003 | AG24: 45865 | AJ24: 300 | AL24: 45875 | AZ24: 45867 | BA24: Hemoclip large(สีส้ม) | BB24: 1 | BC24: 6 | BE24: Hemoclip large(สีส้ม) | BF24: 180 ตัว /กล่อง | BG24: 7100 | BK24: 0 | BN24: 0 | BO24: 45875 | BR24: 59.167 | CB24: 335 | CD24: 2025-12-22 18:16:14.035285 | CF24: 45988.536 | CG24: Y
A25: Round diamond 801 คาดแดง | B25: 513 | C25: ตัว | D25: 14 | E25: Y | O25: 95 | V25: 1 | Y25: 115 | Z25: DM-01-E1-0011 | AG25: 45865 | AJ25: 0 | BA25: Round diamond 801 คาดแดง | BC25: 9 | BE25: Round diamond 801 คาดแดง | BK25: 0 | BN25: 0 | CD25: 2025-12-22 18:16:40.015178 | CG25: Y
A26: Wax knife | B26: 762 | C26: อัน | D26: 14 | E26: Y | O26: 110 | V26: 1 | Y26: 138 | Z26: DM-01-G2-0006 | AG26: 45865 | AJ26: 0 | AL26: 45894 | AZ26: 45846 | BA26: Wax knife | BC26: 9 | BE26: Wax knife | BG26: 110 | BK26: 0 | BN26: 0 | BO26: 45894 | BR26: 110 | CB26: 1062 | CD26: 2025-12-22 18:17:45.837272 | CG26: Y
A27: Suture holding insert | B27: 13095 | C27: ชิ้น | D27: 26 | E27: Y | O27: 13095 | V27: 1 | Y27: 14466 | Z27: 004-12-025-003 | AG27: 45865 | BA27: Suture holding insert | BB27: 1 | BC27: 6 | BE27: Suture holding insert | BR27: 0 | CF27: 45959.615 | CG27: N
A28: Variable screw stainless steel 3.5 mm -shaft | B28: 13116 | C28: ชิ้น | D28: 26 | E28: Y | O28: 1600 | V28: 1 | W28: 13 | Y28: 1821 | Z28: 004-02-128-334 | AG28: 45865 | BA28: Variable screw stainless steel 3.5 mm -shaft | BB28: 1 | BC28: 6 | BE28: Variable screw stainless steel 3.5 mm -shaft | BI28: 1600 | BR28: 0 | CF28: 45950.427 | CG28: N
A29: LCP stainless steel 2.7/3.5 mm. | B29: 13133 | C29: ชิ้น | D29: 26 | E29: Y | O29: 17000 | V29: 1 | W29: 13 | Y29: 18761 | Z29: 004-02-172-013 | AG29: 45865 | BA29: LCP stainless steel 2.7/3.5 mm. | BB29: 1 | BC29: 6 | BE29: LCP stainless steel 2.7/3.5 mm. | BR29: 0 | CF29: 45988.529 | CG29: Y
A30: 2.7/3.5 Fibula Specific LCP | B30: 13129 | C30: ชิ้น | D30: 26 | E30: Y | O30: 18000 | V30: 1 | W30: 13 | Y30: 19861 | Z30: 004-02-165-013 | AG30: 45865 | BA30: 2.7/3.5 Fibula Specific LCP | BB30: 1 | BC30: 6 | BE30: 2.7/3.5 Fibula Specific LCP | BR30: 0 | CF30: 45950.667 | CG30: N
A31: locking srcrew Ti 3.5 mm Pilon | B31: 13124 | C31: ชิ้น | D31: 26 | E31: Y | O31: 2140 | V31: 1 | W31: 13 | Y31: 2415 | Z31: 004-02-128-343 | AG31: 45865 | BA31: locking srcrew Ti 3.5 mm Pilon | BB31: 1 | BC31: 6 | BE31: locking srcrew Ti 3.5 mm Pilon | BR31: 0 | CF31: 45950.668 | CG31: N
A32: Locking-screw Ti 2.7 mm. Conical | B32: 13120 | C32: ชิ้น | D32: 26 | E32: Y | O32: 1000 | V32: 1 | W32: 13 | Y32: 1161 | Z32: 004-02-128-339 | AG32: 45865 | BA32: Locking-screw Ti 2.7 mm. Conical | BB32: 1 | BC32: 6 | BE32: Locking-screw Ti 2.7 mm. Conical | BR32: 0 | CF32: 45950.591 | CG32: N
A33: Waterproof Clear Bandage (พลาสเตอร์ใสกันน้ำปราศจากเชื้อ) | B33: 5082 | C33: ชิ้น | D33: 4 | E33: Y | J33: 3000 | K33: 4500 | O33: 0.83462 | V33: 1 | W33: 70 | Y33: 1.5 | Z33: MS-04-VJ-0001 | AG33: 45865 | AJ33: 3900 | AL33: 45944 | AZ33: 45917 | BA33: Waterproof Clear Bandage (พลาสเตอร์ใสกันน้ำปราศจากเชื้อ) | BB33: 1 | BC33: 6 | BE33: Waterproof Clear Bandage (พลาสเตอร์ใสกันน้ำปราศจากเชื้อ) | BG33: 83.46 | BK33: 0 | BL33: บริษัท ซิลลิค ฟาร์มา จำกัด | BM33: บริษัท ซิลลิค ฟาร์มา จำกัด | BN33: 0 | BO33: 45944 | BP33: 3000 | BQ33: 7500 | BR33: 0.835 | CB33: 345 | CD33: 2026-01-05 13:13:54.266048 | CF33: 45860.758 | CG33: Y
A34: Variable screw stainless steel 3.5 mm | B34: 13114 | C34: ชิ้น | D34: 26 | E34: Y | O34: 2000 | V34: 1 | W34: 13 | Y34: 2261 | Z34: 004-02-128-332 | AG34: 45865 | BA34: Variable screw stainless steel 3.5 mm | BB34: 1 | BC34: 6 | BE34: Variable screw stainless steel 3.5 mm | BR34: 0 | CF34: 45950.426 | CG34: N
A35: 3.5 Locking screw St. | B35: 13119 | C35: ชิ้น | D35: 26 | E35: Y | O35: 1600 | V35: 1 | W35: 13 | Y35: 1821 | Z35: 004-02-128-338 | AG35: 45865 | BA35: 3.5 Locking screw St. | BB35: 1 | BC35: 6 | BE35: 3.5 Locking screw St. | BR35: 0 | CF35: 45968.654 | CG35: N
A36: Fine Blade SM64 | B36: 13090 | C36: ชิ้น | D36: 26 | E36: Y | O36: 8560 | V36: 1 | W36: 13 | Y36: 9477 | Z36: 004-02-092-016 | AG36: 45865 | BA36: Fine Blade SM64 | BB36: 1 | BC36: 6 | BE36: Fine Blade SM64 | BR36: 0 | CF36: 45951.59 | CG36: Y
A37: Variable screw stainless steel 2.7 mm | B37: 13115 | C37: ชิ้น | D37: 26 | E37: Y | O37: 2000 | V37: 1 | W37: 13 | Y37: 2261 | Z37: 004-02-128-333 | AG37: 45865 | BA37: Variable screw stainless steel 2.7 mm | BB37: 1 | BC37: 6 | BE37: Variable screw stainless steel 2.7 mm | BR37: 0 | CF37: 45950.426 | CG37: N
A38: Cannultaed screw 3.7/5.0 mm | B38: 13108 | C38: ชิ้น | D38: 26 | E38: Y | O38: 2500 | V38: 1 | W38: 13 | Y38: 2811 | Z38: 004-02-114-042 | AG38: 45865 | BA38: Cannultaed screw 3.7/5.0 mm | BB38: 1 | BC38: 6 | BE38: Cannultaed screw 3.7/5.0 mm | BR38: 0 | CF38: 45994.492 | CG38: Y
A39: locking srcrew Ti 2.7 mm Pilon | B39: 13125 | C39: ชิ้น | D39: 26 | E39: Y | O39: 2140 | V39: 1 | W39: 13 | Y39: 2415 | Z39: 004-02-128-344 | AG39: 45865 | BA39: locking srcrew Ti 2.7 mm Pilon | BB39: 1 | BC39: 6 | BE39: locking srcrew Ti 2.7 mm Pilon | BR39: 0 | CF39: 45951.431 | CG39: N
A40: LCP Fx around knee 5.0 mm. | B40: 13136 | C40: ชิ้น | D40: 26 | E40: Y | O40: 17000 | V40: 1 | W40: 13 | Y40: 18761 | Z40: 004-02-172-016 | AG40: 45865 | BA40: LCP Fx around knee 5.0 mm. | BB40: 1 | BC40: 6 | BE40: LCP Fx around knee 5.0 mm. | BR40: 0 | CF40: 45999.711 | CG40: Y
...
